Workbook

Sheet Таблица для заполнения
A1: Таблица для заполнения Новая
C2: ед.изм | D2: кол-во
A3: Площадь застройки дома(наружные габариты) | C3: кв.м
A4: Жилая площадь дома(без учета сауны) | C4: кв.м
A5: Высота чистового потолка | C5: м
A7: Утепление пола 150мм | C7: кв.м
A8: Утепление пола 200мм | C8: кв.м
A9: Утепление пола 250мм | C9: кв.м
A10: Чистовое покрытие пола - ламинат | C10: кв.м
A11: Чистовое покрытие пола - керамогранит | C11: кв.м
A14: Погонные метры наружного фасада(доска/брусок, планкен) | C14: м.п.
A17: Погонные метры сдвоенных перегородок(200мм) | C17: м.п.
A18: Погонные метры одинарных перегородок(100мм) | C18: м.п.
A20: Интерьерная доска "в четверть" | C20: м.п.
... A37: Количество санузлов | C37: шт
A38: Наполнение санузлов | D38: ЗАПОЛНИ ВКЛАДКУ №2 !!!

Sheet Наполнение санузла(вкладка №2)
A1: Санузел | B1: кол-во | C1: ед.изм. | D1: Сметная стоимость | E1: Сумма | G1: Наличие водяных точек
A2: Линейный трап | B2: 1 | C2: шт | D2: 11000 | E2: =B2*D2 -> 11000 | G2: Наименование | J2: кол-во | K2: стоимость | L2: сумма
A3: Раздвижная перегородка 1200х2000 | B3: 1 | C3: шт | D3: 60000 | E3: =B3*D3 -> 60000 | G3: Бойлер | J3: 1 | K3: 7000 | L3: =J3*K3 -> 7000
A4: Стационарная стеклянная перегородка 900*2000 | C4: шт | D4: 50000 | E4: =B4*D4 -> 0 | G4: Коллекторный шкаф | J4: 1 | K4: 7000 | L4: =J4*K4 -> 7000
A5: Душевая стойка c смесителем Am/Pm Sunny F0785C900 | B5: 1 | C5: шт | D5: 29000 | E5: =B5*D5 -> 29000 | G5: Подготовка под СМ в с/у | J5: 1 | K5: 7000 | L5: =J5*K5 -> 7000
A6: Гигиенический душ Grohe BauFlow 23632000 с лейкой | C6: шт | D6: 15000 | E6: =B6*D6 -> 0 | G6: Душевая зона в с/у | J6: 1 | K6: 13000 | L6: =J6*K6 -> 13000
A7: Ванна | C7: шт | D7: 70000 | E7: =B7*D7 -> 0 | G7: Раковина на столешнице в с/у | J7: 1 | K7: 7000 | L7: =J7*K7 -> 7000
A8: Смеситель для раковины Am.Pm Gem | B8: 1 | C8: шт | D8: 12000 | E8: =B8*D8 -> 12000 | G8: Инсталляция с унитазом в с/у | J8: 1 | K8: 10000 | L8: =J8*K8 -> 10000
A9: Раковина AM.PM. Func | B9: 1 | C9: шт | D9: 10000 | E9: =B9*D9 -> 10000 | G9: Подготовка под раковину на кухне | J9: 1 | K9: 7000 | L9: =J9*K9 -> 7000
A10: Столешница Масив Альфа 1000*470 | B10: 1 | C10: шт | D10: 7000 | E10: =B10*D10 -> 7000 | G10: Подготовка под ПММ на кухне | J10: 1 | K10: 7000 | L10: =J10*K10 -> 7000
A11: Кронштейн подвесной | B11: 1 | C11: шт | D11: 4500 | E11: =B11*D11 -> 4500 | G11: Соединение фановых труб под домом + ввод воды | J11: 1 | K11: 10000 | L11: =J11*K11 -> 10000
A12: сифон д/раковины без выпуска | B12: 1 | C12: шт | D12: 1500 | E12: =B12*D12 -> 1500 | G12: Монтаж незамерзающего уличного крана | K12: 7000 | L12: =J12*K12 -> 0
A13: выпуск | B13: 1 | C13: шт | D13: 850 | E13: =B13*D13 -> 850 | G13: Монтаж гигиенического душа | K13: 7000 | L13: =J13*K13 -> 0
A14: Труба гофрированная 32*900 | B14: 1 | C14: шт | D14: 650 | E14: =B14*D14 -> 650 | G14: Монтаж скрытой ниши под коммуникации | K14: 7000 | L14: =J14*K14 -> 0
A15: Унитаз напольный | C15: шт | D15: 10000 | E15: =B15*D15 -> 0 | G15: Монтаж стеклянной перегородки | J15: 1 | K15: 7000 | L15: =J15*K15 -> 7000
A16: Бойлер 100л | B16: 1 | C16: шт | D16: 20000 | E16: =B16*D16 -> 20000 | G16: Монтаж ванны | K16: 10000 | L16: =J16*K16 -> 0
A17: Бойлер 50л | C17: шт | D17: 17000 | E17: =B17*D17 -> 0 | G17: Итого: | J17: =SUM(J3:J16) -> 10 | L17: =SUM(L3:L16) -> 82000
A18: Электрический полотенцесушитель Point | B18: 1 | C18: шт | D18: 11000 | E18: =B18*D18 -> 11000
A19: Комплект инсталляция с унитазом AM.PM Crave FlashClean с клавишей Pro L цвет хром, безободковый, с микролифтом | B19: 1 | C19: шт | D19: 30000 | E19: =B19*D19 -> 30000
A20: Греющий кабель | B20: 1 | C20: шт | D20: 2500 | E20: =B20*D20 -> 2500
A21: Комплект фановых труб и фитингов для подключения канализации под домом | B21: 1 | C21: комплект | D21: 5000 | E21: =B21*D21 -> 5000
A22: Незамерзающий уличный кран Unipump | C22: шт | D22: 5000 | E22: =B22*D22 -> 0
A23: Комплект материала для отделки скрытой ниши под коллектор и бойлер | C23: комплект | D23: 5000 | E23: =B23*D23 -> 0
A24: Итоговая комплектация наполнения санузлов: | E24: =SUM(E2:E23) -> 205000

Sheet Таблица обзорная
A1: Объект: | B1: кол-во кв.м. по полу | C1: ='Таблица для заполнения'!D3 -> 0
A3: раздел | B3: ед.изм. | C3: кол-во | D3: ст-ть материала за кв.м. | E3: общая ст-ть материала | F3: ст-ть работ за кв.м. | G3: общая ст-ть работ бригады | H3: з/п спец.рабочих | I3: Итого | J3: Примечание
A4: Проект | B4: кв.м. | C4: =C1 -> 0 | F4: 500 | H4: =C4*F4 -> 0 | I4: =(D4+F4)*C4 -> 0
A5: Пол 150мм | B5: кв.м. | C5: ='Таблица для заполнения'!D7 -> 0 | D5: 3360 | E5: =C5*D5 -> 0 | F5: 950 | G5: =C5*F5 -> 0 | I5: =(D5+F5)*C5 -> 0
A6: Пол 200мм | B6: кв.м. | C6: ='Таблица для заполнения'!D8 -> 0 | D6: 3800 | E6: =C6*D6 -> 0 | F6: 1200 | G6: =C6*F6 -> 0 | I6: =(D6+F6)*C6 -> 0 | N6: не заполняется
A7: Пол 250 мм | B7: кв.м. | C7: ='Таблица для заполнения'!D9 -> 0 | D7: 4200 | E7: =C7*D7 -> 0 | F7: 1050 | G7: =C7*F7 -> 0 | I7: =(D7+F7)*C7 -> 0
A8: Чистовой пол - ламинат | B8: кв.м. | C8: ='Таблица для заполнения'!D10 -> 0 | D8: 2200 | E8: =C8*D8 -> 0 | F8: 600 | G8: =C8*F8 -> 0 | I8: =(D8+F8)*C8 -> 0 | N8: стоимость, заполняется вручную
A9: Чистовой пол -плитка | B9: кв.м. | C9: ='Таблица для заполнения'!D11 -> 0 | D9: 9570 | E9: =C9*D9 -> 0 | F9: 4000 | H9: =C9*F9 -> 0 | I9: =(D9+F9)*C9 -> 0
A10: Наружный фасад - планкен сосновый | B10: кв.м. | C10: ='Таблица для заполнения'!D13*('Таблица для заполнения'!D5+0.95) -> 0 | D10: 2450 | E10: =C10*D10 -> 0 | F10: 900 | G10: =C10*F10 -> 0 | I10: =(D10+F10)*C10 -> 0 | N10: неизменная стоимость
A11: Наружный фасад - комбинированный | B11: кв.м. | C11: ='Таблица для заполнения'!D14*('Таблица для заполнения'!D5+0.95) -> 0 | D11: 2830 | E11: =C11*D11 -> 0 | F11: 1200 | G11: =C11*F11 -> 0 | I11: =(D11+F11)*C11 -> 0
A12: Стенка наружная | B12: кв.м. | C12: ='Таблица для заполнения'!D14*('Таблица для заполнения'!D5+0.15) -> 0 | D12: 2050 | E12: =C12*D12 -> 0 | F12: 600 | G12: =C12*F12 -> 0 | I12: =(D12+F12)*C12 -> 0 | N12: неизменная величина
A13: Перегородка внутр.сдвоенная | B13: кв.м. | C13: ='Таблица для заполнения'!D17*('Таблица для заполнения'!D5+0.15) -> 0 | D13: 2500 | E13: =C13*D13 -> 0 | F13: 1200 | G13: =C13*F13 -> 0 | I13: =(D13+F13)*C13 -> 0
A14: Перегородка внутр. одинарная | B14: кв.м. | C14: ='Таблица для заполнения'!D18*('Таблица для заполнения'!D5+0.15) -> 0 | D14: 1410 | E14: =C14*D14 -> 0 | F14: 600 | G14: =C14*F14 -> 0 | I14: =(D14+F14)*C14 -> 0
A15: Интерьерная доска "в четверть" | B15: кв.м. | C15: ='Таблица для заполнения'!D20*('Таблица для заполнения'!D5+0.05) -> 0 | D15: 1400 | E15: =C15*D15 -> 0 | F15: 600 | G15: =C15*F15 -> 0 | I15: =(D15+F15)*C15 -> 0
A16: Отделка ЛДСП плитами | B16: кв.м. | C16: ='Таблица для заполнения'!D21*('Таблица для заполнения'!D5+0.05) -> 0 | D16: 2000 | E16: =C16*D16 -> 0 | F16: 1500 | G16: =C16*F16 -> 0 | I16: =(D16+F16)*C16 -> 0
A17: Отделка ГКЛ в 2 слоя с покраской | B17: кв.м. | C17: ='Таблица для заполнения'!D22*('Таблица для заполнения'!D5+0.05) -> 0 | D17: 2100 | E17: =C17*D17 -> 0 | F17: 3500 | G17: =C17*F17 -> 0 | I17: =(D17+F17)*C17 -> 0
A18: Отделка МДФ панелями | B18: кв.м. | C18: ='Таблица для заполнения'!D23*('Таблица для заполнения'!D5+0.05) -> 0 | D18: 7000 | E18: =C18*D18 -> 0 | F18: 1500 | G18: =C18*F18 -> 0 | I18: =(D18+F18)*C18 -> 0
A19: Отделка Фанера/рейка | B19: кв.м. | C19: ='Таблица для заполнения'!D24*('Таблица для заполнения'!D5+0.05) -> 0 | D19: 3450 | E19: =C19*D19 -> 0 | F19: 1200 | G19: =C19*F19 -> 0 | I19: =(D19+F19)*C19 -> 0
A20: Крыша двускатная | B20: кв.м. | C20: ='Таблица для заполнения'!D27*1.15 -> 0 | D20: 4720 | E20: =C20*D20 -> 0 | F20: 1500 | G20: =C20*F20 -> 0 | I20: =(D20+F20)*C20 -> 0
A21: Крыша плоская(конструктив) | B21: кв.м. | C21: ='Таблица для заполнения'!D28 -> 0 | D21: 7580 | E21: =C21*D21 -> 0 | F21: 1600 | G21: =C21*F21 -> 0 | I21: =(D21+F21)*C21 -> 0
A22: Наплавка плоской кровли(кровельщик) | B22: кв.м. | C22: ='Таблица для заполнения'!D28 -> 0 | F22: 1000 | H22: =C22*F22 -> 0 | I22: =(D22+F22)*C22 -> 0
A23: Потолок натяжной | B23: кв.м. | C23: ='Таблица для заполнения'!D4 -> 0 | D23: 1000 | E23: =C23*D23 -> 0 | F23: 700 | H23: =C23*F23 -> 0 | I23: =(D23+F23)*C23 -> 0
A24: Подготовка стен санузла с плиткой | B24: кв.м. | C24: ='Таблица для заполнения'!D25*('Таблица для заполнения'!D5+0.05) -> 0 | D24: 6100 | E24: =C24*D24 -> 0 | F24: 4000 | H24: =C24*F24 -> 0 | I24: =(D24+F24)*C24 -> 0
A25: Двери | B25: шт | C25: ='Таблица для заполнения'!D30 -> 0 | D25: 28000 | E25: =C25*D25 -> 0 | F25: 8000 | H25: =C25*F25 -> 0 | I25: =(D25+F25)*C25 -> 0
A26: Сауна | B26: шт | D26: ='Таблица для заполнения'!D31 -> 0 | E26: =D26 -> 0 | F26: ='Таблица для заполнения'!D32 -> 0 | G26: =F26 -> 0 | I26: =D26+F26 -> 0
A27: Отделка окон | B27: шт | C27: ='Таблица для заполнения'!D33 -> 0 | D27: 6000 | E27: =C27*D27 -> 0 | F27: 4000 | G27: =C27*F27 -> 0 | I27: =(D27+F27)*C27 -> 0
A28: Окна+монтаж | B28: шт | C28: ='Таблица для заполнения'!D33 -> 0 | D28: ='Таблица для заполнения'!D34 -> 0 | E28: =D28 -> 0 | F28: 4000 | G28: =C28*F28 -> 0 | I28: =C28*F28+D28 -> 0
A29: Отделка панорамной стенки | B29: шт | C29: ='Таблица для заполнения'!D35 -> 0 | D29: 12000 | E29: =C29*D29 -> 0 | F29: 10000 | G29: =C29*F29 -> 0 | I29: =(D29+F29)*C29 -> 0
A30: Панорамная стенка+монтаж | B30: шт | C30: ='Таблица для заполнения'!D35 -> 0 | D30: ='Таблица для заполнения'!D36 -> 0 | E30: =D30 -> 0 | F30: 10000 | G30: =C30*F30 -> 0 | I30: =D30+F30*C30 -> 0
A31: Кладовщики+малярка | B31: кв.м. | C31: =C1 -> 0 | F31: 1700 | H31: =C31*F31 -> 0 | I31: =C31*F31 -> 0
A32: Электрика | B32: кв.м. | C32: =C1 -> 0 | D32: 2600 | E32: =C32*D32 -> 0 | F32: 1800 | H32: =C32*F32 -> 0 | I32: =(D32+F32)*C32 -> 0
A33: Сантехника | B33: комплект | C33: ='Таблица для заполнения'!D37 -> 0 | D33: 60000 | E33: =C33*D33 -> 0 | F33: ='Наполнение санузла(вкладка №2)'!L17 -> 82000 | H33: =F33 -> 82000 | I33: =E33+H33 -> 82000
A34: Оборудование санузла | B34: комплект | C34: ='Таблица для заполнения'!D37 -> 0 | D34: ='Наполнение санузла(вкладка №2)'!E24 -> 205000 | E34: =C34*D34 -> 0 | I34: =(D34+F34)*C34 -> 0
A35: Конвектора+клапан | B35: кв.м. | C35: =C1 -> 0 | D35: 600 | E35: =C35*D35 -> 0 | F35: 100 | G35: =C35*F35 -> 0 | I35: =(D35+F35)*C35 -> 0
A36: Расходные материалы | B36: кв.м. | C36: =C1 -> 0 | D36: 1600 | E36: =C36*D36 -> 0 | I36: =(D36+F36)*C36 -> 0
A37: Упаковка +сборка | B37: кв.м. | C37: =C1 -> 0 | D37: 600 | E37: =C37*D37 -> 0 | I37: =(D37+F37)*C37 -> 0
E38: =C38*D38 -> 0 | G38: =C38*F38 -> 0 | I38: =(D38+F38)*C38 -> 0
E39: =C39*D39 -> 0 | G39: =C39*F39 -> 0 | I39: =(D39+F39)*C39 -> 0
E40: =C40*D40 -> 0 | G40: =C40*F40 -> 0 | I40: =(D40+F40)*C40 -> 0
E41: =C41*D41 -> 0 | G41: =C41*F41 -> 0 | I41: =(D41+F41)*C41 -> 0
...
